<?xml version="1.0"?>
<robot name="simple_mobile_robot">
 <link name="base_link">
  <visual>
   <geometry>
    <box size="0.4 0.3 0.1"/>
   </geometry>
    
   <material name="blue">
     <color rgba="0 0 1 1"/>

   </material>
  </visual>
 </link>

 <link name="left_wheel">
  <visual>
   <geometry>
    <cylinder radius="0.05" length="0.03"/>
   </geometry>

   <material name="black">
    <color rgba="0.1 0.1 0.1 1"/>
   </material>
  </visual>
 </link>

 <joint name="left_wheel_joint" type="continuous">
   <parent link="base_link"/>
   <child link="left_wheel"/>

   <origin xyz="0 0.17 -0.05" rpy="1.5808 0 0"/>
   <axis xyz="0 1 0"/>
 </joint>
   
 <link name ="right_wheel">
  <visual>
   <geometry>
    <cylinder radius ="0.05" length="0.03"/>
   </geometry>
   <material name="black">
    <color rgba="0.1 0.1 0.1 1"/>
   </material>
  </visual>
 </link>

 <joint name="right_wheel_joint" type="continuous">
   <parent link="base_link"/>
   <child link ="right_wheel"/>
   <origin xyz="0 -0.17 -0.05" rpy="1.5808 0 0"/>
   <axis xyz="0 1 0"/>
 </joint>

 <link name="lidar_link">
  <visual>
   <geometry>
    <cylinder radius="0.04" length="0.05"/>
   </geometry>

   <material name="red">
    <color rgba="1 0 0 1"/>
   </material>
  </visual>
 </link>

 <joint name="lidar_joint" type="fixed">
  <parent link="base_link"/>
  <child link="lidar_link"/>
  <origin xyz="0 0 0.075" rpy="0 0 0"/>
 </joint>

 <link name="camera_link">
  <visual>
   <geometry>
    <box size="0.05 0.05 0.03"/>
   </geometry>

   <material name="green">
    <color rgba="0 1 0 1"/>
   </material>
  </visual>
 </link>

 <joint name="camera_joint" type="fixed">
  <parent link="base_link"/>
  <child link="camera_link"/>
  <origin xyz="0.15 0 0.08" rpy="0 0 0"/>
 </joint>

</robot>









