<?xml version="1.0"?>
<robot name="simple_mobile_robot"
       xmlns:xacro="http://www.ros.org/wiki/xacro">
      


 <xacro:property name="base_length" value="0.4"/>
 <xacro:property name="base_width" value="0.3"/>
 <xacro:property name="base_height" value="0.1"/>

 <xacro:property name="wheel_radius" value="0.05"/>
 <xacro:property name="wheel_width" value="0.03"/>

 <xacro:property name="lidar_radius" value="0.04"/>
 <xacro:property name="lidar_height" value="0.05"/>

 <xacro:property name="camera_size_x" value="0.05"/>
 <xacro:property name="camera_size_y" value="0.05"/>
 <xacro:property name="camera_size_z" value="0.03"/>

 <xacro:property name="imu_size_x" value="0.06"/>
 <xacro:property name="imu_size_y" value="0.06"/>
 <xacro:property name="imu_size_z" value="0.04"/>

 <xacro:property name="caster_radius" value="0.03"/>
 
 <link name="base_link">
  <visual>
   <geometry>
    <box size="${base_length} ${base_width} ${base_height}"/>
   </geometry>
    
   <material name="blue">
     <color rgba="0 0 1 1"/>

   </material>
  </visual>

  <inertial>

   <origin xyz="0 0 0"/>

   <mass value="5.0"/>

   <inertia
      ixx="0.1"
      ixy="0"
      ixz="0"
      iyy="0.1"
      iyz="0"
      izz="0.1"/>

  </inertial>
 </link>

 <link name="left_wheel">
  <visual>
   <geometry>
    <cylinder radius="${wheel_radius}" length="${wheel_width}"/>
   </geometry>

   <material name="black">
    <color rgba="0.1 0.1 0.1 1"/>
   </material>
  </visual>

  <inertial>

   <origin xyz="0 0 0"/>

   <mass value="0.5"/>

   <inertia
      ixx="0.001"
      ixy="0"
      ixz="0"
      iyy="0.001"
      iyz="0"
      izz="0.001"/>

  </inertial>
 </link>

 <joint name="left_wheel_joint" type="continuous">
   <parent link="base_link"/>
   <child link="left_wheel"/>

   <origin xyz="0 0.17 -0.05" rpy="1.5708 0 0"/>
   <axis xyz="0 1 0"/>
 </joint>
   
 <link name ="right_wheel">
  <visual>
   <geometry>
    <cylinder radius="${wheel_radius}" length="${wheel_width}"/>
   </geometry>
   <material name="black">
    <color rgba="0.1 0.1 0.1 1"/>
   </material>
  </visual>

  <inertial>

   <origin xyz="0 0 0"/>

   <mass value="0.5"/>

   <inertia
      ixx="0.001"
      ixy="0"
      ixz="0"
      iyy="0.001"
      iyz="0"
      izz="0.001"/>

  </inertial>
 </link>

 <joint name="right_wheel_joint" type="continuous">
   <parent link="base_link"/>
   <child link ="right_wheel"/>
   <origin xyz="0 -0.17 -0.05" rpy="1.5708 0 0"/>
   <axis xyz="0 1 0"/>
 </joint>

 <link name="lidar_link">
  <visual>
   <geometry>
    <cylinder radius="${lidar_radius}" length="${lidar_height}"/>
   </geometry>

   <material name="red">
    <color rgba="1 0 0 1"/>
   </material>
  </visual>

  <inertial>
   <mass value="0.2"/>

   <inertia
      ixx="0.0001"
      ixy="0"
      ixz="0"
      iyy="0.0001"
      iyz="0"
      izz="0.0001"/>
  </inertial>
 </link>

 <joint name="lidar_joint" type="fixed">
  <parent link="base_link"/>
  <child link="lidar_link"/>
  <origin xyz="0 0 0.075" rpy="0 0 0"/>
 </joint>

 <link name="depth_camera_link">
  <visual>
   <geometry>
    <box size="${camera_size_x} ${camera_size_y} ${camera_size_z}"/>
   </geometry>

   <material name="green">
    <color rgba="0 1 0 1"/>
   </material>
  </visual>

  <inertial>
   <mass value="0.1"/>

   <inertia
      ixx="0.0001"
      ixy="0"
      ixz="0"
      iyy="0.0001"
      iyz="0"
      izz="0.0001"/>
  </inertial>
 </link>

 <joint name="depth_camera_joint" type="fixed">
  <parent link="base_link"/>
  <child link="depth_camera_link"/>
  <origin xyz="0.15 0 0.08" rpy="0 0 0"/>
 </joint>

 <link name="imu_link">
  <visual>
   <geometry>
    <box size="${imu_size_x} ${imu_size_y} ${imu_size_z}"/>
   </geometry>

   <material name="yellow">
    <color rgba="1 1 0 1"/>
   </material>
  </visual>

  <inertial>
   <mass value="0.05"/>

   <inertia
      ixx="0.00001"
      ixy="0"
      ixz="0"
      iyy="0.00001"
      iyz="0"
      izz="0.00001"/>
  </inertial>
 </link>

 <joint name="imu_joint" type="fixed">
  <parent link="base_link"/>
  <child link="imu_link"/>
  <origin xyz="-0.10 0 0.06" rpy="0 0 0"/>
 </joint>

 <link name="caster_wheel">
  <visual>
   <geometry>
    <sphere radius="${caster_radius}"/>
   </geometry>

   <material name="gray">
    <color rgba="0.5 0.5 0.5 1"/>
   </material>
  </visual>

  <inertial>
   <mass value="0.2"/>

   <inertia
      ixx="0.0001"
      ixy="0"
      ixz="0"
      iyy="0.0001"
      iyz="0"
      izz="0.0001"/>
  </inertial>
 </link>

 <joint name="caster_wheel_joint" type="fixed">
  <parent link="base_link"/>
  <child link="caster_wheel"/>
  <origin xyz="-0.15 0 -0.07" rpy="0 0 0"/>
 </joint>

</robot>









